GPU available: True (cuda), used: True
TPU available: False, using: 0 TPU cores
IPU available: False, using: 0 IPUs
HPU available: False, using: 0 HPUs
/home/sasha/segment_barcode/venv/lib/python3.10/site-packages/torch/cuda/__init__.py:146: UserWarning:
NVIDIA GeForce RTX 4060 Ti with CUDA capability sm_89 is not compatible with the current PyTorch installation.
The current PyTorch install supports CUDA capabilities sm_37 sm_50 sm_60 sm_70.
If you want to use the NVIDIA GeForce RTX 4060 Ti GPU with PyTorch, please check the instructions at https://pytorch.org/get-started/locally/
  warnings.warn(incompatible_device_warn.format(device_name, capability, " ".join(arch_list), device_name))
Traceback (most recent call last):
  File "/home/sasha/segment_barcode/train.py", line 54, in <module>
    train(cfg, cfg_m)
  File "/home/sasha/segment_barcode/train.py", line 46, in train
    trainer.fit(model, datamodule)
  File "/home/sasha/segment_barcode/venv/lib/python3.10/site-packages/pytorch_lightning/trainer/trainer.py", line 603, in fit
    call._call_and_handle_interrupt(
  File "/home/sasha/segment_barcode/venv/lib/python3.10/site-packages/pytorch_lightning/trainer/call.py", line 38, in _call_and_handle_interrupt
    return trainer_fn(*args, **kwargs)
  File "/home/sasha/segment_barcode/venv/lib/python3.10/site-packages/pytorch_lightning/trainer/trainer.py", line 645, in _fit_impl
    self._run(model, ckpt_path=self.ckpt_path)
  File "/home/sasha/segment_barcode/venv/lib/python3.10/site-packages/pytorch_lightning/trainer/trainer.py", line 1037, in _run
    self._call_setup_hook()  # allow user to setup lightning_module in accelerator environment
  File "/home/sasha/segment_barcode/venv/lib/python3.10/site-packages/pytorch_lightning/trainer/trainer.py", line 1284, in _call_setup_hook
    self._call_lightning_datamodule_hook("setup", stage=fn)
  File "/home/sasha/segment_barcode/venv/lib/python3.10/site-packages/pytorch_lightning/trainer/trainer.py", line 1361, in _call_lightning_datamodule_hook
    return fn(*args, **kwargs)
  File "/home/sasha/segment_barcode/src/datamodule.py", line 29, in setup
    df = read_dataset_data()
  File "/home/sasha/segment_barcode/src/utils.py", line 17, in read_dataset_data
    df = read_csv(path.join(ANNOTATION_PATH, 'annotations,csv'), sep='\t')
  File "/home/sasha/segment_barcode/venv/lib/python3.10/site-packages/pandas/io/parsers/readers.py", line 1026, in read_csv
    return _read(filepath_or_buffer, kwds)
  File "/home/sasha/segment_barcode/venv/lib/python3.10/site-packages/pandas/io/parsers/readers.py", line 620, in _read
    parser = TextFileReader(filepath_or_buffer, **kwds)
  File "/home/sasha/segment_barcode/venv/lib/python3.10/site-packages/pandas/io/parsers/readers.py", line 1620, in __init__
    self._engine = self._make_engine(f, self.engine)
  File "/home/sasha/segment_barcode/venv/lib/python3.10/site-packages/pandas/io/parsers/readers.py", line 1880, in _make_engine
    self.handles = get_handle(
  File "/home/sasha/segment_barcode/venv/lib/python3.10/site-packages/pandas/io/common.py", line 873, in get_handle
    handle = open(
FileNotFoundError: [Errno 2] No such file or directory: '/home/sasha/segment_barcode/data/annotations,csv'